## 自定义包中的错误处理

这是所有自定义包实现者应该遵守的最佳实践：
1. 在包内部，总是应该从 panic 中 recover：不允许显式的超出包范围的 panic ()
2. 向包的调用者返回错误值（而不是 panic）。

在包内部，特别是在非导出函数中有很深层次的嵌套调用时，对主调函数来说用 panic 来表示应该被翻译成错误的错误场景是很有用的（并且提高了代码可读性）。这在下面的代码中被很好地阐述了。

我们有一个简单的 `parse` 包，用来把输入的字符串解析为整数切片；这个包有自己特殊的 `ParseError`。

当没有东西需要转换或者转换成整数失败时，这个包会 panic（在函数 fields2numbers 中）。但是可导出的 Parse 函数会从 panic 中 recover, 并用所有这些信息返回一个错误给调用者。

为了演示这个过程，在 panic_recover.go 中 调用了 parse 包。不可解析的字符串会导致错误并被打印出来。

示例：

[panic_package.go](./src/panic_package.go)

[./pares](./src/parse/parse.go)